
ERROR __init__.py:97 Error: Directory migrations already exists and is not empty
ERROR __init__.py:97 Error: Directory migrations already exists and is not empty
ERROR __init__.py:98 Error: Directory migrations already exists and is not empty
ERROR checkUser.py:41 decoding to str: need a bytes-like object, NoneType found, 7acc4cfe-1153-4858-9233-72db1321a89e验证码过期
ERROR checkUser.py:42 decoding to str: need a bytes-like object, NoneType found, 3f442abf-48a1-492b-8871-20a65382314e验证码过期
ERROR checkUser.py:42 decoding to str: need a bytes-like object, NoneType found, 1561b4e2-c94a-45a1-9cba-ac7a153e62a7验证码过期
ERROR app.py:1457 Exception on /api_1/register [POST]
Traceback (most recent call last):
  File "/home/lqs/桌面/git/ihome/venv/lib/python3.8/site-packages/flask/app.py", line 2073, in wsgi_app
    response = self.full_dispatch_request()
  File "/home/lqs/桌面/git/ihome/venv/lib/python3.8/site-packages/flask/app.py", line 1518, in full_dispatch_request
    rv = self.handle_user_exception(e)
  File "/home/lqs/桌面/git/ihome/venv/lib/python3.8/site-packages/flask/app.py", line 1516, in full_dispatch_request
    rv = self.dispatch_request()
  File "/home/lqs/桌面/git/ihome/venv/lib/python3.8/site-packages/flask/app.py", line 1502, in dispatch_request
    return self.ensure_sync(self.view_functions[rule.endpoint])(**req.view_args)
  File "/home/lqs/桌面/git/ihome/ihome/api_1/checkUser.py", line 109, in register
    user = models.User(name=mobile, mobile=mobile, passwrod=pwd)
  File "<string>", line 4, in __init__
  File "/home/lqs/桌面/git/ihome/venv/lib/python3.8/site-packages/sqlalchemy/orm/state.py", line 480, in _initialize_instance
    manager.dispatch.init_failure(self, args, kwargs)
  File "/home/lqs/桌面/git/ihome/venv/lib/python3.8/site-packages/sqlalchemy/util/langhelpers.py", line 70, in __exit__
    compat.raise_(
  File "/home/lqs/桌面/git/ihome/venv/lib/python3.8/site-packages/sqlalchemy/util/compat.py", line 207, in raise_
    raise exception
  File "/home/lqs/桌面/git/ihome/venv/lib/python3.8/site-packages/sqlalchemy/orm/state.py", line 477, in _initialize_instance
    return manager.original_init(*mixed[1:], **kwargs)
  File "/home/lqs/桌面/git/ihome/venv/lib/python3.8/site-packages/sqlalchemy/orm/decl_base.py", line 1154, in _declarative_constructor
    raise TypeError(
TypeError: 'passwrod' is an invalid keyword argument for User
ERROR checkUser.py:102 decoding to str: need a bytes-like object, NoneType found, redis链接错误
ERROR app.py:1457 Exception on /api_1/register [POST]
Traceback (most recent call last):
  File "/home/lqs/桌面/git/ihome/venv/lib/python3.8/site-packages/flask/app.py", line 2073, in wsgi_app
    response = self.full_dispatch_request()
  File "/home/lqs/桌面/git/ihome/venv/lib/python3.8/site-packages/flask/app.py", line 1518, in full_dispatch_request
    rv = self.handle_user_exception(e)
  File "/home/lqs/桌面/git/ihome/venv/lib/python3.8/site-packages/flask/app.py", line 1516, in full_dispatch_request
    rv = self.dispatch_request()
  File "/home/lqs/桌面/git/ihome/venv/lib/python3.8/site-packages/flask/app.py", line 1502, in dispatch_request
    return self.ensure_sync(self.view_functions[rule.endpoint])(**req.view_args)
  File "/home/lqs/桌面/git/ihome/ihome/api_1/checkUser.py", line 109, in register
    user = models.User(name=mobile, mobile=mobile, passwrod=pwd)
  File "<string>", line 4, in __init__
  File "/home/lqs/桌面/git/ihome/venv/lib/python3.8/site-packages/sqlalchemy/orm/state.py", line 480, in _initialize_instance
    manager.dispatch.init_failure(self, args, kwargs)
  File "/home/lqs/桌面/git/ihome/venv/lib/python3.8/site-packages/sqlalchemy/util/langhelpers.py", line 70, in __exit__
    compat.raise_(
  File "/home/lqs/桌面/git/ihome/venv/lib/python3.8/site-packages/sqlalchemy/util/compat.py", line 207, in raise_
    raise exception
  File "/home/lqs/桌面/git/ihome/venv/lib/python3.8/site-packages/sqlalchemy/orm/state.py", line 477, in _initialize_instance
    return manager.original_init(*mixed[1:], **kwargs)
  File "/home/lqs/桌面/git/ihome/venv/lib/python3.8/site-packages/sqlalchemy/orm/decl_base.py", line 1154, in _declarative_constructor
    raise TypeError(
TypeError: 'passwrod' is an invalid keyword argument for User
ERROR app.py:1457 Exception on /api_1/register [POST]
Traceback (most recent call last):
  File "/home/lqs/桌面/git/ihome/venv/lib/python3.8/site-packages/flask/app.py", line 2073, in wsgi_app
    response = self.full_dispatch_request()
  File "/home/lqs/桌面/git/ihome/venv/lib/python3.8/site-packages/flask/app.py", line 1518, in full_dispatch_request
    rv = self.handle_user_exception(e)
  File "/home/lqs/桌面/git/ihome/venv/lib/python3.8/site-packages/flask/app.py", line 1516, in full_dispatch_request
    rv = self.dispatch_request()
  File "/home/lqs/桌面/git/ihome/venv/lib/python3.8/site-packages/flask/app.py", line 1502, in dispatch_request
    return self.ensure_sync(self.view_functions[rule.endpoint])(**req.view_args)
  File "/home/lqs/桌面/git/ihome/ihome/api_1/checkUser.py", line 110, in register
    user.password(pwd)
  File "/home/lqs/桌面/git/ihome/ihome/models.py", line 37, in password
    raise AttributeError("这个属性只能设置，不能读取")
AttributeError: 这个属性只能设置，不能读取
ERROR checkUser.py:102 decoding to str: need a bytes-like object, NoneType found, redis链接错误
ERROR checkUser.py:42 decoding to str: need a bytes-like object, NoneType found, 8483ed37-0371-432b-865d-68618395fd7e验证码过期
ERROR checkUser.py:145 'Redis' object has no attribute 'expried', redis连接错误
ERROR checkUser.py:145 'Redis' object has no attribute 'expried', redis连接错误
ERROR checkUser.py:145 'Redis' object has no attribute 'exprie', redis连接错误
ERROR checkUser.py:145 'Redis' object has no attribute 'exprie', redis连接错误
ERROR checkUser.py:145 'Redis' object has no attribute 'exprie', redis连接错误
ERROR app.py:1457 Exception on /api_1/session [GET]
Traceback (most recent call last):
  File "/home/lqs/桌面/git/ihome/venv/lib/python3.8/site-packages/flask/app.py", line 2073, in wsgi_app
    response = self.full_dispatch_request()
  File "/home/lqs/桌面/git/ihome/venv/lib/python3.8/site-packages/flask/app.py", line 1518, in full_dispatch_request
    rv = self.handle_user_exception(e)
  File "/home/lqs/桌面/git/ihome/venv/lib/python3.8/site-packages/flask/app.py", line 1516, in full_dispatch_request
    rv = self.dispatch_request()
  File "/home/lqs/桌面/git/ihome/venv/lib/python3.8/site-packages/flask/app.py", line 1502, in dispatch_request
    return self.ensure_sync(self.view_functions[rule.endpoint])(**req.view_args)
  File "/home/lqs/桌面/git/ihome/ihome/api_1/checkUser.py", line 167, in login_check
    return jsonify(errno=statusCode.OK, errmsg="true", data={user: user})
  File "/home/lqs/桌面/git/ihome/venv/lib/python3.8/site-packages/flask/json/__init__.py", line 355, in jsonify
    f"{dumps(data, indent=indent, separators=separators)}\n",
  File "/home/lqs/桌面/git/ihome/venv/lib/python3.8/site-packages/flask/json/__init__.py", line 133, in dumps
    rv = _json.dumps(obj, **kwargs)
  File "/usr/lib/python3.8/json/__init__.py", line 234, in dumps
    return cls(
  File "/usr/lib/python3.8/json/encoder.py", line 199, in encode
    chunks = self.iterencode(o, _one_shot=True)
  File "/usr/lib/python3.8/json/encoder.py", line 257, in iterencode
    return _iterencode(o, 0)
TypeError: keys must be str, int, float, bool or None, not User
ERROR app.py:1457 Exception on /api_1/session [GET]
Traceback (most recent call last):
  File "/home/lqs/桌面/git/ihome/venv/lib/python3.8/site-packages/flask/app.py", line 2073, in wsgi_app
    response = self.full_dispatch_request()
  File "/home/lqs/桌面/git/ihome/venv/lib/python3.8/site-packages/flask/app.py", line 1518, in full_dispatch_request
    rv = self.handle_user_exception(e)
  File "/home/lqs/桌面/git/ihome/venv/lib/python3.8/site-packages/flask/app.py", line 1516, in full_dispatch_request
    rv = self.dispatch_request()
  File "/home/lqs/桌面/git/ihome/venv/lib/python3.8/site-packages/flask/app.py", line 1502, in dispatch_request
    return self.ensure_sync(self.view_functions[rule.endpoint])(**req.view_args)
  File "/home/lqs/桌面/git/ihome/ihome/api_1/checkUser.py", line 167, in login_check
    return jsonify(errno=statusCode.OK, errmsg="true", data={user: user})
  File "/home/lqs/桌面/git/ihome/venv/lib/python3.8/site-packages/flask/json/__init__.py", line 355, in jsonify
    f"{dumps(data, indent=indent, separators=separators)}\n",
  File "/home/lqs/桌面/git/ihome/venv/lib/python3.8/site-packages/flask/json/__init__.py", line 133, in dumps
    rv = _json.dumps(obj, **kwargs)
  File "/usr/lib/python3.8/json/__init__.py", line 234, in dumps
    return cls(
  File "/usr/lib/python3.8/json/encoder.py", line 199, in encode
    chunks = self.iterencode(o, _one_shot=True)
  File "/usr/lib/python3.8/json/encoder.py", line 257, in iterencode
    return _iterencode(o, 0)
TypeError: keys must be str, int, float, bool or None, not User
ERROR app.py:1457 Exception on /api_1/session [GET]
Traceback (most recent call last):
  File "/home/lqs/桌面/git/ihome/venv/lib/python3.8/site-packages/flask/app.py", line 2073, in wsgi_app
    response = self.full_dispatch_request()
  File "/home/lqs/桌面/git/ihome/venv/lib/python3.8/site-packages/flask/app.py", line 1518, in full_dispatch_request
    rv = self.handle_user_exception(e)
  File "/home/lqs/桌面/git/ihome/venv/lib/python3.8/site-packages/flask/app.py", line 1516, in full_dispatch_request
    rv = self.dispatch_request()
  File "/home/lqs/桌面/git/ihome/venv/lib/python3.8/site-packages/flask/app.py", line 1502, in dispatch_request
    return self.ensure_sync(self.view_functions[rule.endpoint])(**req.view_args)
  File "/home/lqs/桌面/git/ihome/ihome/api_1/checkUser.py", line 167, in login_check
    return jsonify(errno=statusCode.OK, errmsg="true", data={user: user})
  File "/home/lqs/桌面/git/ihome/venv/lib/python3.8/site-packages/flask/json/__init__.py", line 355, in jsonify
    f"{dumps(data, indent=indent, separators=separators)}\n",
  File "/home/lqs/桌面/git/ihome/venv/lib/python3.8/site-packages/flask/json/__init__.py", line 133, in dumps
    rv = _json.dumps(obj, **kwargs)
  File "/usr/lib/python3.8/json/__init__.py", line 234, in dumps
    return cls(
  File "/usr/lib/python3.8/json/encoder.py", line 199, in encode
    chunks = self.iterencode(o, _one_shot=True)
  File "/usr/lib/python3.8/json/encoder.py", line 257, in iterencode
    return _iterencode(o, 0)
TypeError: keys must be str, int, float, bool or None, not User
ERROR app.py:1457 Exception on /api_1/session [GET]
Traceback (most recent call last):
  File "/home/lqs/桌面/git/ihome/venv/lib/python3.8/site-packages/flask/app.py", line 2073, in wsgi_app
    response = self.full_dispatch_request()
  File "/home/lqs/桌面/git/ihome/venv/lib/python3.8/site-packages/flask/app.py", line 1518, in full_dispatch_request
    rv = self.handle_user_exception(e)
  File "/home/lqs/桌面/git/ihome/venv/lib/python3.8/site-packages/flask/app.py", line 1516, in full_dispatch_request
    rv = self.dispatch_request()
  File "/home/lqs/桌面/git/ihome/venv/lib/python3.8/site-packages/flask/app.py", line 1502, in dispatch_request
    return self.ensure_sync(self.view_functions[rule.endpoint])(**req.view_args)
  File "/home/lqs/桌面/git/ihome/ihome/api_1/checkUser.py", line 167, in login_check
    return jsonify(errno=statusCode.OK, errmsg="true", data={user: user})
  File "/home/lqs/桌面/git/ihome/venv/lib/python3.8/site-packages/flask/json/__init__.py", line 355, in jsonify
    f"{dumps(data, indent=indent, separators=separators)}\n",
  File "/home/lqs/桌面/git/ihome/venv/lib/python3.8/site-packages/flask/json/__init__.py", line 133, in dumps
    rv = _json.dumps(obj, **kwargs)
  File "/usr/lib/python3.8/json/__init__.py", line 234, in dumps
    return cls(
  File "/usr/lib/python3.8/json/encoder.py", line 199, in encode
    chunks = self.iterencode(o, _one_shot=True)
  File "/usr/lib/python3.8/json/encoder.py", line 257, in iterencode
    return _iterencode(o, 0)
TypeError: keys must be str, int, float, bool or None, not User
ERROR app.py:1457 Exception on /api_1/session [GET]
Traceback (most recent call last):
  File "/home/lqs/桌面/git/ihome/venv/lib/python3.8/site-packages/flask/app.py", line 2073, in wsgi_app
    response = self.full_dispatch_request()
  File "/home/lqs/桌面/git/ihome/venv/lib/python3.8/site-packages/flask/app.py", line 1518, in full_dispatch_request
    rv = self.handle_user_exception(e)
  File "/home/lqs/桌面/git/ihome/venv/lib/python3.8/site-packages/flask/app.py", line 1516, in full_dispatch_request
    rv = self.dispatch_request()
  File "/home/lqs/桌面/git/ihome/venv/lib/python3.8/site-packages/flask/app.py", line 1502, in dispatch_request
    return self.ensure_sync(self.view_functions[rule.endpoint])(**req.view_args)
  File "/home/lqs/桌面/git/ihome/ihome/api_1/checkUser.py", line 167, in login_check
    return jsonify(errno=statusCode.OK, errmsg="true", data={"user": user})
  File "/home/lqs/桌面/git/ihome/venv/lib/python3.8/site-packages/flask/json/__init__.py", line 355, in jsonify
    f"{dumps(data, indent=indent, separators=separators)}\n",
  File "/home/lqs/桌面/git/ihome/venv/lib/python3.8/site-packages/flask/json/__init__.py", line 133, in dumps
    rv = _json.dumps(obj, **kwargs)
  File "/usr/lib/python3.8/json/__init__.py", line 234, in dumps
    return cls(
  File "/usr/lib/python3.8/json/encoder.py", line 199, in encode
    chunks = self.iterencode(o, _one_shot=True)
  File "/usr/lib/python3.8/json/encoder.py", line 257, in iterencode
    return _iterencode(o, 0)
  File "/home/lqs/桌面/git/ihome/venv/lib/python3.8/site-packages/flask/json/__init__.py", line 57, in default
    return super().default(o)
  File "/usr/lib/python3.8/json/encoder.py", line 179, in default
    raise TypeError(f'Object of type {o.__class__.__name__} '
TypeError: Object of type User is not JSON serializable
ERROR app.py:1457 Exception on /api_1/session [GET]
Traceback (most recent call last):
  File "/home/lqs/桌面/git/ihome/venv/lib/python3.8/site-packages/flask/app.py", line 2073, in wsgi_app
    response = self.full_dispatch_request()
  File "/home/lqs/桌面/git/ihome/venv/lib/python3.8/site-packages/flask/app.py", line 1518, in full_dispatch_request
    rv = self.handle_user_exception(e)
  File "/home/lqs/桌面/git/ihome/venv/lib/python3.8/site-packages/flask/app.py", line 1516, in full_dispatch_request
    rv = self.dispatch_request()
  File "/home/lqs/桌面/git/ihome/venv/lib/python3.8/site-packages/flask/app.py", line 1502, in dispatch_request
    return self.ensure_sync(self.view_functions[rule.endpoint])(**req.view_args)
  File "/home/lqs/桌面/git/ihome/ihome/api_1/checkUser.py", line 167, in login_check
    return jsonify(errno=statusCode.OK, errmsg="true", data={"user": user})
  File "/home/lqs/桌面/git/ihome/venv/lib/python3.8/site-packages/flask/json/__init__.py", line 355, in jsonify
    f"{dumps(data, indent=indent, separators=separators)}\n",
  File "/home/lqs/桌面/git/ihome/venv/lib/python3.8/site-packages/flask/json/__init__.py", line 133, in dumps
    rv = _json.dumps(obj, **kwargs)
  File "/usr/lib/python3.8/json/__init__.py", line 234, in dumps
    return cls(
  File "/usr/lib/python3.8/json/encoder.py", line 199, in encode
    chunks = self.iterencode(o, _one_shot=True)
  File "/usr/lib/python3.8/json/encoder.py", line 257, in iterencode
    return _iterencode(o, 0)
  File "/home/lqs/桌面/git/ihome/venv/lib/python3.8/site-packages/flask/json/__init__.py", line 57, in default
    return super().default(o)
  File "/usr/lib/python3.8/json/encoder.py", line 179, in default
    raise TypeError(f'Object of type {o.__class__.__name__} '
TypeError: Object of type User is not JSON serializable
